# 无法捕捉的Exception
2016/09/16 13:20:00
Javascript


## 不起作用的catch

下面这个例子，`catch`永远不会起到作用，尽管这个`Error`的确是`f()`导致的。我们先定义一个简单的函数，它在1秒后抛出异常：

```js
function f() { setTimeout(() => { throw new Error() }, 1000) }
```

调用它，并尝试捕获那个异常，你会发现这个`catch`起不了作用：

```js
try { f() }
catch (e) { console.log(`I caught ${e}`) }
```

这是因为Javascript里，使用`setTimeout`之类的函数时，调用栈信息并没有跟随着那个回调函数。


## 为什么这样？

仔细想想，似乎这样也合情合理。异常不像变量，变量直接通过闭包保存下来是没有问题的，它只是一个值，就像块石头一样待在那儿。

但是异常是需要代码处理的，这种异步产生的异常，你就是知道了它的源头，也处理不了了。

比如上面例子里面的`f`，一秒钟后，那个异常被触发的时候，`f()`早就执行完了，因此那个`try`也早就执行完了。


## 如何应对

最直观的解决办法当然是直接在传给`setTimeout`的函数内部完成异常处理。也就是给异常捕获的代码换个位置，比如对于上面那个例子，可以把里面的匿名函数提取出来：

```js
function sub() {
  try { throw new Error() }
  catch (e) { console.log("I caught:", e) }
}
```

然后就不存在上述问题了

```js
function f() { setTimeout(sub, 1000) }
f()
```

不过这种方式有点儿麻烦，而且一点也不巧妙。好在一般不需要这样处理，因为现在我们有了Promise。
